Workbook

Sheet README
A1: Phase 3 — Build
A3: Purpose | B3: Deliver MVP and subsequent increments through sprint-by-sprint execution with sustained quality.
A5: Duration | B5: 10-18 months. MVP complete by Month 16; full scope by Month 34.
A7: Sprint cadence | B7: 2-week sprints. Sprint zero runs overlapping final Design weeks for squad formation.
A9: Squads | B9: 4 squads aligned to epic streams: Ops Core, Switching Safety, Integration & Data, Platform & Observability. Each squad ~6-8 people led by a Sr Eng.
A11: Entry criteria | B11: MVP ADRs accepted. MVP Epics decomposed to initial story level. Platform foundation operational. Definition of Ready and Definition of Done agreed.
A12: Exit criteria | B12: MVP in UAT, remaining scope nearing complete, parallel-run decisions informed by actual performance.
A14: Tabs
A15: 1. Story Backlog | B15: All stories across all epics. Status progresses Backlog → Refined → Ready → In Sprint → In Test → Done.
A16: 2. Sprint Backlog | B16: Active sprint + next two sprints. Detailed commitment and progress.
A17: 3. Capacity Calculator | B17: Per-sprint team capacity factoring allocation, PTO, ceremonies.
A18: 4. Velocity Tracker | B18: Sprint velocity history with trend.
A19: 5. Sprint Retrospectives | B19: Keep / Stop / Start items and actions across sprints.
A20: 6. Impediment Log | B20: Blockers preventing progress. Owner and escalation path.
A21: 7. Feature Flag Register | B21: Flags, enablement schedule, per-district rollout state.
A22: 8. Tech Debt Register | B22: Deferred work with paydown priority.
A23: 9. Code Review Findings | B23: Systemic patterns from code review prompts worth tracking.
A24: 10. Build Phase Risks | B24: Build-specific risks distinct from program risks.
A25: 11. Build Dashboard | B25: KPI roll-up: velocity, defect escape, AC coverage, tech debt trend.
A27: Discipline
A28: Definition of Ready | B28: INVEST-checked; Gherkin AC present; size estimated; dependencies resolved; safety-critical Product Council informed.
A29: Definition of Done | B29: Code merged; tests passing; AC demonstrated; code reviewed; docs updated; audit events verified; feature flag configured if applicable; observability instrumentation present.
A30: Safety-critical gating | B30: Safety-critical stories pair-programmed. Code review by Sr Eng + safety-aware reviewer. Product Council demo before accepting.
A31: Tech debt limit | B31: Tech debt ratio capped at 15% of story points. Exceeding triggers paydown sprint or scope decision.
A32: Rotations | B32: Junior and mid engineers rotate across squads on a 2-sprint cadence. Seniors anchor. Prevents knowledge silos.

Sheet 1. Story Backlog
A1: Story Backlog (program-wide)
A2: All stories across all Epics. Status advances Backlog → Refined → Ready → In Sprint → In Test → Done.
A3: Story IDs: US-[EPIC-SHORT]-[NUMBER]. Safety-critical stories require pair-program + dual review + Product Council demo.
A4: Story ID | B4: Title | C4: Epic | D4: Squad | E4: Priority | F4: Safety-Critical? | G4: Points | H4: Status | I4: Sprint | J4: Assignee | K4: DoR Check | L4: DoD Check | M4: Dependencies | N4: Notes
A5: US-SCADA-001 | B5: Consume SCADA event stream with consumer groups | C5: E-OPS-01 | D5: Integration & Data | E5: Must | F5: N | G5: 8 | H5: Done | I5: S-01 | J5: Eng-A1 | K5: Y | L5: Y | M5: Platform foundation ready
A6: US-SCADA-002 | B6: Deduplicate events within sliding 15-minute window | C6: E-OPS-01 | D6: Integration & Data | E6: Must | F6: N | G6: 5 | H6: Done | I6: S-02 | J6: Eng-A2 | K6: Y | L6: Y | M6: US-SCADA-001
A7: US-SCADA-003 | B7: Parse and validate IEC 61850 event schema | C7: E-OPS-01 | D7: Integration & Data | E7: Must | F7: N | G7: 5 | H7: Done | I7: S-02 | J7: Eng-A2 | K7: Y | L7: Y | M7: INT-01 signed
A8: US-SCADA-004 | B8: Correlate events to known devices via device catalog | C8: E-OPS-01 | D8: Integration & Data | E8: Must | F8: N | G8: 8 | H8: In Test | I8: S-03 | J8: Eng-A1 | K8: Y | L8: N | M8: MIG-01 device catalog loaded
A9: US-SCADA-005 | B9: Handle orphan events (no device match) | C9: E-OPS-01 | D9: Integration & Data | E9: Must | F9: N | G9: 5 | H9: In Sprint | I9: S-04 | J9: Eng-A3 | K9: Y | L9: N | M9: US-SCADA-004
A10: US-SCADA-006 | B10: Event replay on consumer restart | C10: E-OPS-01 | D10: Integration & Data | E10: Must | F10: N | G10: 5 | H10: In Sprint | I10: S-04 | J10: Eng-A2 | K10: Y | L10: N | M10: US-SCADA-001
A11: US-SCADA-007 | B11: Daily reconciliation: detect state divergence from SCADA | C11: E-OPS-01 | D11: Integration & Data | E11: Must | F11: N | G11: 13 | H11: Ready | I11: S-05 | J11: Eng-A1 | K11: Y | L11: N | M11: FM-13 mitigation
A12: US-CARD-001 | B12: Auto-create card from qualifying SCADA fault event | C12: E-OPS-02 | D12: Ops Core | E12: Must | F12: N | G12: 8 | H12: Done | I12: S-02 | J12: Eng-B2 | K12: Y | L12: Y | M12: US-SCADA-004
A13: US-CARD-002 | B13: Manual card creation by operator | C13: E-OPS-02 | D13: Ops Core | E13: Must | F13: N | G13: 5 | H13: Done | I13: S-02 | J13: Eng-B3 | K13: Y | L13: Y | M13: SM-01 formalized
A14: US-CARD-003 | B14: Bulk card open during storm event | C14: E-OPS-02 | D14: Ops Core | E14: Must | F14: N | G14: 8 | H14: Done | I14: S-03 | J14: Eng-B2 | K14: Y | L14: Y | M14: US-CARD-001 | N14: Feature-flagged
A15: US-CARD-004 | B15: Card state transitions (Open through Closed) | C15: E-OPS-02 | D15: Ops Core | E15: Must | F15: N | G15: 13 | H15: Done | I15: S-03 | J15: Eng-B1 | K15: Y | L15: Y | M15: SM-01 | N15: Complex state machine
A16: US-CARD-005 | B16: Card assignment to operator | C16: E-OPS-02 | D16: Ops Core | E16: Must | F16: N | G16: 3 | H16: In Test | I16: S-04 | J16: Eng-B3 | K16: Y | L16: N | M16: US-CARD-004
A17: US-CARD-006 | B17: Add notes and attachments to card | C17: E-OPS-02 | D17: Ops Core | E17: Should | F17: N | G17: 5 | H17: In Sprint | I17: S-04 | J17: Eng-B4 | K17: Y | L17: N | M17: Cross-cutting attachment service
A18: US-CARD-007 | B18: Link cards (parent/child relationships) | C18: E-OPS-02 | D18: Ops Core | E18: Must | F18: N | G18: 5 | H18: Ready | I18: S-05 | J18: Eng-B2 | K18: Y | L18: N | M18: US-CARD-004
A19: US-CARD-008 | B19: Card detail view UI | C19: E-OPS-02 | D19: Ops Core | E19: Must | F19: N | G19: 8 | H19: Ready | I19: S-05 | J19: Eng-FE1 | K19: Y | L19: N | M19: US-CARD-004
A20: US-CARD-009 | B20: Close card with cause code selection | C20: E-OPS-02 | D20: Ops Core | E20: Must | F20: N | G20: 5 | H20: Refined | I20: S-06 | J20: Eng-B3 | K20: N | L20: N | M20: Cause code catalog migrated
A21: US-CARD-010 | B21: Card reopen workflow with reason capture | C21: E-OPS-02 | D21: Ops Core | E21: Must | F21: N | G21: 5 | H21: Refined | I21: S-06 | J21: Eng-B3 | K21: N | L21: N | M21: US-CARD-009
A22: US-SWEXEC-001 | B22: Start switching order execution | C22: E-OPS-04 | D22: Switching Safety | E22: Must | F22: Y | G22: 8 | H22: In Sprint | I22: S-04 | J22: Eng-C1+Eng-C2 | K22: Y | L22: N | M22: SM-02, SM-03 finalized | N22: Pair-program
A23: US-SWEXEC-002 | B23: Execute step with precondition verification | C23: E-OPS-04 | D23: Switching Safety | E23: Must | F23: Y | G23: 13 | H23: Ready | I23: S-05 | J23: Eng-C1+Eng-C3 | K23: Y | L23: N | M23: BR-SW-042 safety-critical | N23: Pair-program
A24: US-SWEXEC-003 | B24: Mark step complete with postcondition check | C24: E-OPS-04 | D24: Switching Safety | E24: Must | F24: Y | G24: 13 | H24: Ready | I24: S-05 | J24: Eng-C1+Eng-C2 | K24: Y | L24: N | M24: SCADA telemetry integration | N24: Pair-program
A25: US-SWEXEC-004 | B25: Pause and resume switching order | C25: E-OPS-04 | D25: Switching Safety | E25: Must | F25: Y | G25: 8 | H25: Refined | I25: S-06 | J25: Eng-C1+Eng-C3 | K25: N | L25: N | M25: US-SWEXEC-001 | N25: Pair-program
A26: US-SWEXEC-005 | B26: Reverse completed steps (abandonment) | C26: E-OPS-04 | D26: Switching Safety | E26: Must | F26: Y | G26: 13 | H26: Refined | I26: S-07 | J26: Eng-C1+Eng-C2 | K26: N | L26: N | M26: G-003 resolved | N26: Pair-program
A27: US-SWEXEC-006 | B27: Supervisor override of precondition with reason | C27: E-OPS-04 | D27: Switching Safety | E27: Must | F27: Y | G27: 8 | H27: Refined | I27: S-07 | J27: Eng-C1+Eng-C3 | K27: N | L27: N | M27: BR-SW-050 override policy | N27: Pair-program; absolute BRs blocked
A28: US-SWEXEC-007 | B28: Shift handoff during active switching order | C28: E-OPS-04 | D28: Switching Safety | E28: Should | F28: Y | G28: 8 | H28: Backlog | I28: S-08 | K28: N | L28: N | M28: US-SWEXEC-001, FM-10 addressed
A29: US-CLR-001 | B29: Issue clearance for device(s) | C29: E-OPS-05 | D29: Switching Safety | E29: Must | F29: Y | G29: 8 | H29: Ready | I29: S-06 | J29: Eng-C4 | K29: Y | L29: N | M29: SM-04 finalized
A30: US-CLR-002 | B30: Release clearance with crew acknowledgment | C30: E-OPS-05 | D30: Switching Safety | E30: Must | F30: Y | G30: 5 | H30: Refined | I30: S-06 | J30: Eng-C4 | K30: N | L30: N | M30: US-CLR-001
A31: US-CLR-003 | B31: Check clearance scope overlap invariant | C31: E-OPS-05 | D31: Switching Safety | E31: Must | F31: Y | G31: 8 | H31: Refined | I31: S-07 | J31: Eng-C4+Eng-C2 | K31: N | L31: N | M31: No-overlap invariant from SM-04 | N31: Safety-critical invariant
A32: US-CLR-004 | B32: Clearance audit retrieval view | C32: E-OPS-05 | D32: Switching Safety | E32: Must | F32: Y | G32: 5 | H32: Backlog | I32: S-08 | K32: N | L32: N | M32: US-CLR-001, audit service
A33: US-FWS-001 | B33: Dispatch work order via outbox pattern | C33: E-INT-02 | D33: Integration & Data | E33: Must | F33: N | G33: 8 | H33: Ready | I33: S-05 | J33: Eng-A3 | K33: Y | L33: N | M33: INT-02 signed, ADR-006
A34: US-FWS-002 | B34: Idempotent retry with exponential backoff | C34: E-INT-02 | D34: Integration & Data | E34: Must | F34: N | G34: 5 | H34: Ready | I34: S-06 | J34: Eng-A3 | K34: Y | L34: N | M34: US-FWS-001
A35: US-FWS-003 | B35: Receive field status updates | C35: E-INT-02 | D35: Integration & Data | E35: Must | F35: N | G35: 5 | H35: Refined | I35: S-06 | J35: Eng-A2 | K35: N | L35: N | M35: INT-02 signed
A36: US-FWS-004 | B36: Reconciliation job for dispatch drift | C36: E-INT-02 | D36: Integration & Data | E36: Must | F36: N | G36: 8 | H36: Backlog | I36: S-08 | K36: N | L36: N | M36: US-FWS-001
A37: US-AUTH-001 | B37: SAML SSO authentication flow | C37: E-PLT-01 | D37: Platform & Observability | E37: Must | F37: N | G37: 8 | H37: Done | I37: S-01 | J37: Eng-D1 | K37: Y | L37: Y | M37: INT-05 signed
A38: US-AUTH-002 | B38: RBAC role assignment and enforcement | C38: E-PLT-01 | D38: Platform & Observability | E38: Must | F38: N | G38: 13 | H38: Done | I38: S-02 | J38: Eng-D1 | K38: Y | L38: Y | M38: Role catalog
A39: US-AUTH-003 | B39: District-scope attribute enforcement | C39: E-PLT-01 | D39: Platform & Observability | E39: Must | F39: Y | G39: 8 | H39: Done | I39: S-03 | J39: Eng-D1 | K39: Y | L39: Y | M39: ADR-010
A40: US-AUTH-004 | B40: Supervisor override authorization with step-up MFA | C40: E-PLT-01 | D40: Platform & Observability | E40: Must | F40: Y | G40: 8 | H40: In Test | I40: S-04 | J40: Eng-D1 | K40: Y | L40: N | M40: US-AUTH-002, US-AUTH-003
...

Sheet 2. Sprint Backlog
A1: Sprint Backlog — active + next two sprints
A2: Focused view of current execution. Full backlog lives in tab 1.
A3: Status progresses: To Do → In Progress → In Review → In Test → Done. Daily standup updates these.
A4: Sprint | B4: Story ID | C4: Title | D4: Assignee | E4: Squad | F4: Points | G4: Task Status | H4: Hrs Remaining | I4: Blockers | J4: Notes
A5: S-04 | B5: US-SCADA-005 | C5: Handle orphan events | D5: Eng-A3 | E5: Integration & Data | F5: 5 | G5: In Progress | H5: 6
A6: S-04 | B6: US-SCADA-006 | C6: Event replay on consumer restart | D6: Eng-A2 | E6: Integration & Data | F6: 5 | G6: In Review | H6: 2 | J6: PR #284
A7: S-04 | B7: US-CARD-005 | C7: Card assignment to operator | D7: Eng-B3 | E7: Ops Core | F7: 3 | G7: In Test | H7: 0
A8: S-04 | B8: US-CARD-006 | C8: Add notes and attachments to card | D8: Eng-B4 | E8: Ops Core | F8: 5 | G8: In Progress | H8: 8 | I8: Attachment service API
A9: S-04 | B9: US-SWEXEC-001 | C9: Start switching order execution | D9: Eng-C1+Eng-C2 | E9: Switching Safety | F9: 8 | G9: In Progress | H9: 18 | J9: Pair-programmed
A10: S-04 | B10: US-AUTH-004 | C10: Supervisor override with step-up MFA | D10: Eng-D1 | E10: Platform & Observability | F10: 8 | G10: In Test | H10: 0 | J10: Product Council demo scheduled
A11: S-04 | B11: US-OBS-003 | C11: SCADA consumer lag dashboard | D11: Eng-D3 | E11: Platform & Observability | F11: 3 | G11: In Review | H11: 1 | J11: PR #290
A12: S-04 | B12: US-CARD-011 | C12: Card priority escalation rule | D12: Eng-B2 | E12: Ops Core | F12: 3 | G12: Done | H12: 0
A13: S-04 | B13: TS-01 | C13: Reduce flaky SCADA integration test | D13: Eng-A1 | E13: Integration & Data | F13: 2 | G13: Done | H13: 0 | J13: Tech debt pay-down
A14: S-05 | B14: US-SCADA-007 | C14: SCADA reconciliation job | D14: Eng-A1 | E14: Integration & Data | F14: 13 | G14: To Do | H14: 40 | J14: SP-11 input
A15: S-05 | B15: US-CARD-007 | C15: Link cards parent/child | D15: Eng-B2 | E15: Ops Core | F15: 5 | G15: To Do | H15: 16
A16: S-05 | B16: US-CARD-008 | C16: Card detail view | D16: Eng-FE1 | E16: Ops Core | F16: 8 | G16: To Do | H16: 24
A17: S-05 | B17: US-SWEXEC-002 | C17: Execute step with precondition | D17: Eng-C1+Eng-C3 | E17: Switching Safety | F17: 13 | G17: To Do | H17: 40 | J17: Pair-programmed; BR-SW-042
A18: S-05 | B18: US-SWEXEC-003 | C18: Mark step complete with postcondition | D18: Eng-C1+Eng-C2 | E18: Switching Safety | F18: 13 | G18: To Do | H18: 40 | J18: Pair-programmed
A19: S-05 | B19: US-FWS-001 | C19: Dispatch via outbox pattern | D19: Eng-A3 | E19: Integration & Data | F19: 8 | G19: To Do | H19: 24
A20: S-06 | B20: US-CARD-009 | C20: Close card with cause code | D20: Eng-B3 | E20: Ops Core | F20: 5 | G20: To Do | H20: 0 | J20: Refinement needed
A21: S-06 | B21: US-CARD-010 | C21: Card reopen workflow | D21: Eng-B3 | E21: Ops Core | F21: 5 | G21: To Do | H21: 0 | J21: Refinement needed
A22: S-06 | B22: US-SWEXEC-004 | C22: Pause and resume switching order | D22: Eng-C1+Eng-C3 | E22: Switching Safety | F22: 8 | G22: To Do | H22: 0 | J22: Pair-programmed
A23: S-06 | B23: US-CLR-001 | C23: Issue clearance for device | D23: Eng-C4 | E23: Switching Safety | F23: 8 | G23: To Do | H23: 0
A24: S-06 | B24: US-CLR-002 | C24: Release clearance | D24: Eng-C4 | E24: Switching Safety | F24: 5 | G24: To Do | H24: 0
A25: S-06 | B25: US-FWS-002 | C25: Idempotent retry | D25: Eng-A3 | E25: Integration & Data | F25: 5 | G25: To Do | H25: 0
A26: S-06 | B26: US-FWS-003 | C26: Receive field status updates | D26: Eng-A2 | E26: Integration & Data | F26: 5 | G26: To Do | H26: 0
A29: CURRENT SPRINT (S-04)
A30: Points committed: | B30: =SUMIF(A5:A300,"S-04",F5:F300) -> 42
A31: Points done: | B31: =SUMIFS(F5:F300,A5:A300,"S-04",G5:G300,"Done") -> 5
A32: % complete: | B32: =IFERROR(B31/B30,0) -> 0.11904762
A33: Hrs remaining: | B33: =SUMIF(A5:A300,"S-04",H5:H300) -> 35

Sheet 3. Capacity Calculator
A1: Sprint Capacity Calculator
A2: Capacity per sprint factoring team roster, allocation %, PTO, holidays, ceremonies.
A3: Update allocation per sprint. Points capacity = (available hours / focus factor) — focus factor calibrated from velocity data.
A4: Person / Role | B4: Squad | C4: Hrs/Day | D4: Allocation % | E4: Sprint Days | F4: PTO Days | G4: Ceremony Hrs | H4: Avail Hrs | I4: Hrs/Point (calibrated) | J4: Pts Capacity | K4: Notes
A5: Chief Architect | B5: Cross-squad | C5: 8 | D5: 10 | E5: 10 | F5: 0 | G5: 8 | H5: =C5*(E5-F5)*D5/100-G5 -> 0 | I5: 8 | J5: =IFERROR(H5/I5,0) -> 0 | K5: Design oversight
A6: Sr Eng Deputy | B6: Cross-squad | C6: 8 | D6: 30 | E6: 10 | F6: 0 | G6: 10 | H6: =C6*(E6-F6)*D6/100-G6 -> 14 | I6: 8 | J6: =IFERROR(H6/I6,0) -> 1.75 | K6: Mentoring + reviews
A7: Sr Eng A (Int&Data lead) | B7: Integration & Data | C7: 8 | D7: 80 | E7: 10 | F7: 0 | G7: 10 | H7: =C7*(E7-F7)*D7/100-G7 -> 54 | I7: 7 | J7: =IFERROR(H7/I7,0) -> 7.7142857
A8: Sr Eng B (Ops Core lead) | B8: Ops Core | C8: 8 | D8: 80 | E8: 10 | F8: 0 | G8: 10 | H8: =C8*(E8-F8)*D8/100-G8 -> 54 | I8: 7 | J8: =IFERROR(H8/I8,0) -> 7.7142857
A9: Sr Eng C (Switching lead) | B9: Switching Safety | C9: 8 | D9: 80 | E9: 10 | F9: 0 | G9: 10 | H9: =C9*(E9-F9)*D9/100-G9 -> 54 | I9: 7 | J9: =IFERROR(H9/I9,0) -> 7.7142857 | K9: Safety-critical focus
A10: Sr Eng D (Platform lead) | B10: Platform & Observability | C10: 8 | D10: 80 | E10: 10 | F10: 0 | G10: 10 | H10: =C10*(E10-F10)*D10/100-G10 -> 54 | I10: 7 | J10: =IFERROR(H10/I10,0) -> 7.7142857
A11: Mid Eng 1 | B11: Integration & Data | C11: 8 | D11: 90 | E11: 10 | F11: 1 | G11: 6 | H11: =C11*(E11-F11)*D11/100-G11 -> 58.8 | I11: 8 | J11: =IFERROR(H11/I11,0) -> 7.35
A12: Mid Eng 2 | B12: Integration & Data | C12: 8 | D12: 90 | E12: 10 | F12: 0 | G12: 6 | H12: =C12*(E12-F12)*D12/100-G12 -> 66 | I12: 8 | J12: =IFERROR(H12/I12,0) -> 8.25
A13: Mid Eng 3 | B13: Ops Core | C13: 8 | D13: 90 | E13: 10 | F13: 0 | G13: 6 | H13: =C13*(E13-F13)*D13/100-G13 -> 66 | I13: 8 | J13: =IFERROR(H13/I13,0) -> 8.25
A14: Mid Eng 4 | B14: Ops Core | C14: 8 | D14: 90 | E14: 10 | F14: 2 | G14: 6 | H14: =C14*(E14-F14)*D14/100-G14 -> 51.6 | I14: 8 | J14: =IFERROR(H14/I14,0) -> 6.45 | K14: PTO S-04
A15: Mid Eng 5 | B15: Switching Safety | C15: 8 | D15: 90 | E15: 10 | F15: 0 | G15: 6 | H15: =C15*(E15-F15)*D15/100-G15 -> 66 | I15: 8 | J15: =IFERROR(H15/I15,0) -> 8.25
A16: Mid Eng 6 | B16: Platform & Observability | C16: 8 | D16: 90 | E16: 10 | F16: 0 | G16: 6 | H16: =C16*(E16-F16)*D16/100-G16 -> 66 | I16: 8 | J16: =IFERROR(H16/I16,0) -> 8.25
A17: Jr Eng 1 | B17: Integration & Data | C17: 8 | D17: 80 | E17: 10 | F17: 0 | G17: 6 | H17: =C17*(E17-F17)*D17/100-G17 -> 58 | I17: 10 | J17: =IFERROR(H17/I17,0) -> 5.8 | K17: Ramping
A18: Jr Eng 2 | B18: Ops Core | C18: 8 | D18: 80 | E18: 10 | F18: 0 | G18: 6 | H18: =C18*(E18-F18)*D18/100-G18 -> 58 | I18: 10 | J18: =IFERROR(H18/I18,0) -> 5.8 | K18: Ramping
A19: Jr Eng 3 | B19: Switching Safety | C19: 8 | D19: 80 | E19: 10 | F19: 0 | G19: 6 | H19: =C19*(E19-F19)*D19/100-G19 -> 58 | I19: 10 | J19: =IFERROR(H19/I19,0) -> 5.8 | K19: Ramping
A20: Jr Eng 4 | B20: Platform & Observability | C20: 8 | D20: 80 | E20: 10 | F20: 0 | G20: 6 | H20: =C20*(E20-F20)*D20/100-G20 -> 58 | I20: 10 | J20: =IFERROR(H20/I20,0) -> 5.8 | K20: Ramping
A21: FE Tech Lead | B21: Ops Core | C21: 8 | D21: 70 | E21: 10 | F21: 0 | G21: 8 | H21: =C21*(E21-F21)*D21/100-G21 -> 48 | I21: 7 | J21: =IFERROR(H21/I21,0) -> 6.8571429
A22: FE Dev 1 | B22: Ops Core | C22: 8 | D22: 90 | E22: 10 | F22: 0 | G22: 6 | H22: =C22*(E22-F22)*D22/100-G22 -> 66 | I22: 8 | J22: =IFERROR(H22/I22,0) -> 8.25
A23: FE Dev 2 | B23: Switching Safety | C23: 8 | D23: 90 | E23: 10 | F23: 0 | G23: 6 | H23: =C23*(E23-F23)*D23/100-G23 -> 66 | I23: 8 | J23: =IFERROR(H23/I23,0) -> 8.25
A24: FE Dev 3 | B24: Platform & Observability | C24: 8 | D24: 90 | E24: 10 | F24: 0 | G24: 6 | H24: =C24*(E24-F24)*D24/100-G24 -> 66 | I24: 8 | J24: =IFERROR(H24/I24,0) -> 8.25
A25: QA Auto 1 | B25: Cross-squad | C25: 8 | D25: 80 | E25: 10 | F25: 0 | G25: 6 | H25: =C25*(E25-F25)*D25/100-G25 -> 58 | I25: 6 | J25: =IFERROR(H25/I25,0) -> 9.6666667 | K25: Ops Core + Switching
A26: QA Auto 2 | B26: Cross-squad | C26: 8 | D26: 80 | E26: 10 | F26: 0 | G26: 6 | H26: =C26*(E26-F26)*D26/100-G26 -> 58 | I26: 6 | J26: =IFERROR(H26/I26,0) -> 9.6666667 | K26: Integration + Platform
A27: Integration Eng 1 | B27: Integration & Data | C27: 8 | D27: 80 | E27: 10 | F27: 0 | G27: 6 | H27: =C27*(E27-F27)*D27/100-G27 -> 58 | I27: 7 | J27: =IFERROR(H27/I27,0) -> 8.2857143
A28: Integration Eng 2 | B28: Integration & Data | C28: 8 | D28: 80 | E28: 10 | F28: 0 | G28: 6 | H28: =C28*(E28-F28)*D28/100-G28 -> 58 | I28: 7 | J28: =IFERROR(H28/I28,0) -> 8.2857143
A29: DBA | B29: Cross-squad | C29: 8 | D29: 40 | E29: 10 | F29: 0 | G29: 4 | H29: =C29*(E29-F29)*D29/100-G29 -> 28 | I29: 8 | J29: =IFERROR(H29/I29,0) -> 3.5
A30: DevOps 1 | B30: Platform & Observability | C30: 8 | D30: 60 | E30: 10 | F30: 0 | G30: 6 | H30: =C30*(E30-F30)*D30/100-G30 -> 42 | I30: 8 | J30: =IFERROR(H30/I30,0) -> 5.25
A31: DevOps 2 | B31: Platform & Observability | C31: 8 | D31: 60 | E31: 10 | F31: 0 | G31: 6 | H31: =C31*(E31-F31)*D31/100-G31 -> 42 | I31: 8 | J31: =IFERROR(H31/I31,0) -> 5.25
A32: Sec Eng | B32: Cross-squad | C32: 8 | D32: 30 | E32: 10 | F32: 0 | G32: 4 | H32: =C32*(E32-F32)*D32/100-G32 -> 20 | I32: 8 | J32: =IFERROR(H32/I32,0) -> 2.5
A33: BA 1 | B33: Ops Core + Switching | C33: 8 | D33: 90 | E33: 10 | F33: 0 | G33: 6 | H33: =C33*(E33-F33)*D33/100-G33 -> 66 | I33: 8 | J33: =IFERROR(H33/I33,0) -> 8.25
A34: BA 2 | B34: Integration + Platform | C34: 8 | D34: 90 | E34: 10 | F34: 0 | G34: 6 | H34: =C34*(E34-F34)*D34/100-G34 -> 66 | I34: 8 | J34: =IFERROR(H34/I34,0) -> 8.25
A37: SQUAD CAPACITY
A38: Integration & Data | H38: =SUMIFS(H5:H34,B5:B34,"Integration & Data*") -> 352.8 | J38: =SUMIFS(J5:J34,B5:B34,"Integration & Data*") -> 45.685714
A39: Ops Core | H39: =SUMIFS(H5:H34,B5:B34,"Ops Core*") -> 409.6 | J39: =SUMIFS(J5:J34,B5:B34,"Ops Core*") -> 51.571429
A40: Switching Safety | H40: =SUMIFS(H5:H34,B5:B34,"Switching Safety*") -> 244 | J40: =SUMIFS(J5:J34,B5:B34,"Switching Safety*") -> 30.014286
A41: Platform & Observability | H41: =SUMIFS(H5:H34,B5:B34,"Platform & Observability*") -> 328 | J41: =SUMIFS(J5:J34,B5:B34,"Platform & Observability*") -> 40.514286
A42: Cross-squad | H42: =SUMIFS(H5:H34,B5:B34,"Cross-squad*") -> 178 | J42: =SUMIFS(J5:J34,B5:B34,"Cross-squad*") -> 27.083333
...

Sheet 4. Velocity Tracker
A1: Velocity Tracker
A2: Sprint-by-sprint velocity history. Use 3-sprint rolling average for commitment forecasts.
A3: Committed vs. Completed gap indicates estimation accuracy; widening gap is a signal to investigate.
A4: Sprint | B4: Start Date | C4: End Date | D4: Committed Pts | E4: Completed Pts | F4: Delta | G4: Completed Stories | H4: Carry-over Stories | I4: Defects Escaped | J4: Notes
A5: S-00 | B5: 2026-07-06 | C5: 2026-07-17 | D5: 0 | E5: 0 | F5: =E5-D5 -> 0 | G5: 0 | H5: 0 | I5: 0 | J5: Sprint zero — squad formation, tooling, environment
A6: S-01 | B6: 2026-07-20 | C6: 2026-07-31 | D6: 45 | E6: 42 | F6: =E6-D6 -> -3 | G6: 5 | H6: 1 | I6: 0 | J6: First delivery sprint
A7: S-02 | B7: 2026-08-03 | C7: 2026-08-14 | D7: 55 | E7: 53 | F7: =E7-D7 -> -2 | G7: 7 | H7: 1 | I7: 1 | J7: Findings: 1 defect on US-AUTH-002
A8: S-03 | B8: 2026-08-17 | C8: 2026-08-28 | D8: 58 | E8: 55 | F8: =E8-D8 -> -3 | G8: 6 | H8: 2 | I8: 0
A9: S-04 | B9: 2026-08-31 | C9: 2026-09-11 | D9: 62 | E9: 0 | F9: =E9-D9 -> -62 | G9: 0 | H9: 0 | I9: 0 | J9: Current — in flight
A10: S-05 | B10: 2026-09-14 | C10: 2026-09-25 | D10: 64 | E10: 0 | F10: =E10-D10 -> -64 | G10: 0 | H10: 0 | I10: 0 | J10: Planned
A11: S-06 | B11: 2026-09-28 | C11: 2026-10-09 | D11: 64 | E11: 0 | F11: =E11-D11 -> -64 | G11: 0 | H11: 0 | I11: 0 | J11: Planned
A12: S-07 | B12: 2026-10-12 | C12: 2026-10-23 | D12: 64 | E12: 0 | F12: =E12-D12 -> -64 | G12: 0 | H12: 0 | I12: 0 | J12: Planned
A13: S-08 | B13: 2026-10-26 | C13: 2026-11-06 | D13: 64 | E13: 0 | F13: =E13-D13 -> -64 | G13: 0 | H13: 0 | I13: 0 | J13: Planned
A14: S-09 | B14: 2026-11-09 | C14: 2026-11-20 | D14: 64 | E14: 0 | F14: =E14-D14 -> -64 | G14: 0 | H14: 0 | I14: 0 | J14: Planned
A15: S-10 | B15: 2026-11-23 | C15: 2026-12-04 | D15: 50 | E15: 0 | F15: =E15-D15 -> -50 | G15: 0 | H15: 0 | I15: 0 | J15: Planned — Thanksgiving short
A16: S-11 | B16: 2026-12-07 | C16: 2026-12-18 | D16: 64 | E16: 0 | F16: =E16-D16 -> -64 | G16: 0 | H16: 0 | I16: 0 | J16: Planned
A19: METRICS
A20: Completed sprints avg velocity: | B20: =AVERAGEIFS(E5:E16,E5:E16,">0") -> 50
A21: 3-sprint rolling avg: | B21: =AVERAGE(E6:E8) -> 50
A22: Avg estimation accuracy (completed/committed): | B22: =IFERROR(AVERAGEIFS(E5:E16,E5:E16,">0")/AVERAGEIFS(D5:D16,E5:E16,">0"),0) -> 0.94936709
A23: Total defects escaped to date: | B23: =SUM(I5:I16) -> 1
A24: Avg defects per sprint (completed): | B24: =IFERROR(SUMIFS(I5:I16,E5:E16,">0")/COUNTIFS(E5:E16,">0"),0) -> 0.33333333

Sheet 5. Sprint Retrospectives
A1: Sprint Retrospectives
A2: Keep / Stop / Start items from each sprint retro. Actions carried forward until addressed.
A3: Theme column helps identify systemic patterns — a theme appearing 3+ sprints signals a structural issue.
A4: Sprint | B4: Date | C4: Type | D4: Item | E4: Theme | F4: Action Owner | G4: Status | H4: Notes
A5: S-01 | B5: 2026-07-31 | C5: Keep | D5: Squad-of-4 pair programming for switching safety stories | E5: Safety discipline | F5: Sr Eng C | G5: Ongoing
A6: S-01 | B6: 2026-07-31 | C6: Keep | D6: Daily 10-min 'architecture sync' for Sr Engs only | E6: Coordination | F6: Sr Eng Deputy | G6: Ongoing
A7: S-01 | B7: 2026-07-31 | C7: Stop | D7: Merging PRs without test run on target branch | E7: Quality | F7: All Sr Engs | G7: Closed | H7: CI gate added
A8: S-01 | B8: 2026-07-31 | C8: Start | D8: Documenting AC-to-test mapping in story comments | E8: Traceability | F8: QA Auto 1 | G8: Ongoing
A9: S-02 | B9: 2026-08-14 | C9: Keep | D9: Pair programming for safety-critical continues | E9: Safety discipline | F9: Sr Eng C | G9: Ongoing
A10: S-02 | B10: 2026-08-14 | C10: Stop | D10: Story estimation in squad meetings — move to planning poker async | E10: Estimation | F10: All Sr Engs | G10: Closed | H10: Switched to async poker
A11: S-02 | B11: 2026-08-14 | C11: Start | D11: Weekly BR-code walkthrough for US-AUTH-002 defect root cause | E11: Learning | F11: Sec Eng | G11: Closed | H11: Addressed
A12: S-02 | B12: 2026-08-14 | C12: Keep | D12: 15-min 'intended design' review before coding safety stories | E12: Safety discipline | F12: Sr Eng C | G12: Ongoing
A13: S-03 | B13: 2026-08-28 | C13: Stop | D13: Jr Eng picking up safety-critical stories solo | E13: Safety discipline | F13: Sr Eng C | G13: Closed | H13: Safety = pair programmed always
A14: S-03 | B14: 2026-08-28 | C14: Start | D14: Integration test fixtures shared across squads | E14: Test efficiency | F14: QA Auto 2 | G14: In Progress
A15: S-03 | B15: 2026-08-28 | C15: Keep | D15: Friday afternoon DAB updates to architect-on-call | E15: Architecture discipline | F15: Sr Eng Deputy | G15: Ongoing
A16: S-03 | B16: 2026-08-28 | C16: Start | D16: Tech debt log walkthrough every retro (new practice) | E16: Tech debt management | F16: Sr Eng Deputy | G16: Ongoing | H16: Prevents debt invisibility
A17: S-03 | B17: 2026-08-28 | C17: Stop | D17: Accepting stories without AC-to-test mapping | E17: Quality | F17: POs | G17: Closed | H17: Now in DoR

Sheet 6. Impediment Log
A1: Impediment Log
A2: Anything blocking progress. Escalation path: Sr Eng → PM → Steering (48hr internal / 24hr external cap).
A3: Impediments open >5 business days trigger automatic PM escalation.
A4: ID | B4: Raised Date | C4: Description | D4: Category | E4: Severity | F4: Affected Story/Stories | G4: Owner | H4: Status | I4: Resolved Date | J4: Notes
A5: I-01 | B5: 2026-07-22 | C5: SCADA test environment credentials not rotated; team blocked on US-SCADA-001 | D5: External | E5: High | F5: US-SCADA-001 | G5: Sec Eng | H5: Closed | I5: 2026-07-23 | J5: Resolved <24hr; good
A6: I-02 | B6: 2026-07-30 | C6: Field Work vendor API doc ambiguity on idempotency — blocks US-FWS design | D6: External | E6: Medium | F6: US-FWS-001, US-FWS-002 | G6: Integration Architect | H6: Closed | I6: 2026-08-08 | J6: Vendor clarification + amended INT-02
A7: I-03 | B7: 2026-08-05 | C7: Flyway migration rollback approach unclear for complex migration MIG-06 | D7: Internal | E7: Medium | F7: E-PLT-05 dependent | G7: Data Arch | H7: Closed | I7: 2026-08-12 | J7: Pattern established
A8: I-04 | B8: 2026-08-18 | C8: Integration test env DB performance insufficient for US-SCADA-004 validation | D8: Internal | E8: Medium | F8: US-SCADA-004 | G8: DevOps 1 | H8: Closed | I8: 2026-08-22 | J8: Env rebuilt with SSD
A9: I-05 | B9: 2026-08-26 | C9: GIS vendor unreachable — topology sync validation delayed | D9: External | E9: Medium | F9: US-GIS-001 | G9: Integration Architect | H9: Open | J9: Escalated to program manager
A10: I-06 | B10: 2026-09-02 | C10: Security Architect bandwidth constraint — review queue building | D10: Internal | E10: Medium | F10: Multiple | G10: Program Manager | H10: Open | J10: Considering secondary reviewer
A11: I-07 | B11: 2026-09-04 | C11: Field Work System test environment differs from prod in auth flow | D11: External | E11: Low | F11: US-FWS-001 | G11: Integration Architect | H11: Open | J11: Vendor agreed to align; ETA 2 weeks
A12: I-08 | B12: 2026-09-05 | C12: PM capacity split with cutover planning starting early | D12: Internal | E12: Low | F12: None specific | G12: Program Manager | H12: Open | J12: Preparing deputy PM
A13: I-09 | B13: 2026-09-08 | C13: Kafka consumer lag monitoring noise — false alert fatigue | D13: Internal | E13: Low | F13: Observability | G13: DevOps 2 | H13: Open
A14: I-10 | B14: 2026-09-09 | C14: Product Council operator unavailable for US-SWEXEC-001 demo | D14: Internal | E14: Medium | F14: US-SWEXEC-001 | G14: Product Owner | H14: Open | J14: Reschedule next week

Sheet 7. Feature Flag Register
A1: Feature Flag Register
A2: Every runtime flag with purpose, owner, and removal criteria. Flags exist for: cutover coordination, incremental rollout, risky changes, kill switches.
A3: Flags with no removal criteria = permanent flags. These need explicit justification.
A4: Flag ID | B4: Flag Name | C4: Purpose | D4: Type | E4: Default | F4: Owner | G4: Created | H4: Removal Criteria / Sunset Date | I4: Status | J4: Notes
A5: F-01 | B5: card.auto-create-enabled | C5: Enable auto-card creation from SCADA events per district | D5: Cutover | E5: false | F5: Ops PO | G5: 2026-07-29 | H5: Remove after full cutover (all districts) | I5: Active | J5: Per-district value
A6: F-02 | B6: card.bulk-open-enabled | C6: Enable bulk card opening during storm declaration | D6: Cutover | E6: false | F6: Ops PO | G6: 2026-08-12 | H6: Remove after full cutover | I6: Active
A7: F-03 | B7: swexec.execute-enabled | C7: Safety gate on switching order execution | D7: Safety kill-switch | E7: false | F7: Ops PO | G7: 2026-09-03 | H7: Permanent — never remove | I7: Permanent | J7: Emergency kill
A8: F-04 | B8: clearance.issue-enabled | C8: Safety gate on clearance issuance | D8: Safety kill-switch | E8: false | F8: Ops PO | G8: 2026-09-03 | H8: Permanent | I8: Permanent | J8: Emergency kill
A9: F-05 | B9: fws.dispatch-enabled | C9: Enable field work dispatch integration per district | D9: Cutover | E9: false | F9: Integration Lead | G9: 2026-08-22 | H9: Remove after full cutover | I9: Active
A10: F-06 | B10: scada.reconciliation-enabled | C10: Enable daily SCADA reconciliation job | D10: Cutover | E10: false | F10: Integration Lead | G10: 2026-09-04 | H10: Enable at pilot cutover | I10: Active
A11: F-07 | B11: ui.new-dashboard-enabled | C11: Rollout of new operator dashboard UI | D11: Rollout | E11: false | F11: UX Lead | G11: 2026-08-28 | H11: Full user migration complete + 2 weeks | I11: Active
A12: F-08 | B12: audit.archival-enabled | C12: Enable cold-storage archival of audit events | D12: Rollout | E12: false | F12: Sec Eng | G12: 2026-09-09 | H12: After production validation | I12: Active
A13: F-09 | B13: reporting.replica-isolated | C13: Use dedicated reporting replica | D13: Cutover | E13: false | F13: DBA | G13: 2026-09-09 | H13: After SP-11 validation | I13: Active
A14: F-10 | B14: storm.degraded-mode-enabled | C14: Auto-shed UI features during extreme load | D14: Safety / resilience | E14: false | F14: Chief Architect | G14: planned | H14: After full cutover + storm validation | I14: Planned | J14: Enable AFTER validating in UAT
A15: F-11 | B15: sw.new-state-machine | C15: New state machine library vs legacy switch-based | D15: Migration | E15: false | F15: Sr Eng C | G15: 2026-09-09 | H15: After SP-06 + validation | I15: Active | J15: ADR-017 rollout
A16: F-12 | B16: observability.fine-grained-tracing | C16: Enable fine-grained tracing (performance cost) | D16: Diagnostic | E16: false | F16: DevOps 2 | G16: 2026-08-20 | H16: Permanent — runtime toggle for incidents | I16: Permanent | J16: Diagnostic tool
A17: F-13 | B17: api.v2-enabled | C17: v2 API available (breaking changes from v1) | D17: Rollout | E17: false | F17: Integration Lead | G17: planned | H17: After all consumers migrated | I17: Planned
A18: F-14 | B18: cutover.legacy-read-only | C18: Put legacy system in read-only mode | D18: Cutover | E18: false | F18: Program Manager | G18: planned | H18: Per-district: activated at cutover; removed at hypercare exit | I18: Planned | J18: Coordinated with legacy ops
A19: F-15 | B19: mvp.non-mvp-features-hidden | C19: Hide non-MVP features from UI until ready | D19: Rollout | E19: true | F19: UX Lead | G19: 2026-08-01 | H19: As each non-MVP feature ships | I19: Active

Sheet 8. Tech Debt Register
A1: Tech Debt Register
A2: Deliberate deferrals tracked and prioritized. Target: debt ratio <= 15% of points/sprint.
A3: Every debt item links to why it was incurred and paydown plan. Safety-critical debt has 30-day resolution cap.
A4: Debt ID | B4: Description | C4: Category | D4: Severity | E4: Origin Sprint | F4: Linked Story | G4: Effort (pts) | H4: Priority | I4: Target Sprint | J4: Status | K4: Notes
A5: TD-01 | B5: Temp in-memory dedup cache (US-SCADA-002) — move to Redis for HA | C5: Architecture | D5: High | E5: S-02 | F5: US-SCADA-002 | G5: 5 | H5: H | I5: S-07 | J5: Open | K5: ADR-004 proper implementation
A6: TD-02 | B6: Shared test fixtures scattered across squad repos | C6: Testing | D6: Medium | E6: S-01 | F6: multiple | G6: 5 | H6: M | I6: S-06 | J6: In Progress | K6: Retro action S-03
A7: TD-02b | B7: Audit event envelope versioning deferred to v2 | C7: Design | D7: Low | E7: S-01 | F7: US-AUDIT-002 | G7: 3 | H7: L | I7: S-12 | J7: Open | K7: Not limiting now
A8: TD-03 | B8: Switching step precondition library — hardcoded vs data-driven | C8: Architecture | D8: High | E8: S-04 | F8: US-SWEXEC-002 | G8: 8 | H8: H | I8: S-09 | J8: Open | K8: Technical ceiling approaching; SP-09 outcome
A9: TD-04 | B9: UI component library drift across Ops Core and Switching squads | C9: UI | D9: Medium | E9: S-02 | F9: multiple | G9: 8 | H9: M | I9: S-08 | J9: Open | K9: FE tech lead addressing
A10: TD-05 | B10: Integration test env data refresh manual — should be automated | C10: Tooling | D10: Medium | E10: S-01 | F10: N/A | G10: 5 | H10: M | I10: S-08 | J10: Open | K10: DevOps queue
A11: TD-06 | B11: FW System dispatch: first implementation skipped idempotency key in body | C11: Integration | D11: High | E11: S-05 | F11: US-FWS-001 | G11: 3 | H11: H | I11: S-06 | J11: Open | K11: Pay down before cutover
A12: TD-07 | B12: Log levels inconsistent across squads | C12: Observability | D12: Low | E12: S-03 | F12: multiple | G12: 3 | H12: L | I12: S-10 | J12: Open | K12: Standards doc needed
A13: TD-08 | B13: Defect US-AUTH-002 root cause: missing test scenario for district cross-scope | C13: Test coverage | D13: High | E13: S-02 | F13: US-AUTH-002 | G13: 5 | H13: H | I13: S-05 | J13: Closed | K13: Addressed
A14: TD-09 | B14: Kafka consumer offset commit pattern manual — should use auto-commit with care | C14: Integration | D14: Medium | E14: S-02 | F14: US-SCADA-001 | G14: 3 | H14: M | I14: S-09 | J14: Open
A15: TD-10 | B15: DB connection pool sizing not load-tested | C15: Platform | D15: Medium | E15: S-03 | F15: N/A | G15: 3 | H15: M | I15: S-09 | J15: Open | K15: Spike planned
A16: TD-11 | B16: Feature flag evaluation hot path allocates on every call | C16: Performance | D16: Low | E16: S-04 | F16: all flagged stories | G16: 2 | H16: L | I16: S-12 | J16: Open
A17: TD-12 | B17: No circuit breaker on CIS integration calls | C17: Resilience | D17: Medium | E17: S-04 | F17: US-CIS-001 planned | G17: 5 | H17: M | I17: S-08 | J17: Open | K17: Will be issue at storm load
A18: TD-13 | B18: Migration reconciliation scripts one-off — generalize | C18: Migration | D18: Medium | E18: S-03 | F18: E-PLT-05 | G18: 5 | H18: M | I18: S-10 | J18: Open | K18: Data Arch
A19: TD-14 | B19: Safety-critical: grounding rule check bypass code path possible via race condition | C19: SAFETY | D19: CRITICAL | E19: S-04 | F19: US-SWEXEC-002 | G19: 8 | H19: CRITICAL | I19: S-05 | J19: Open | K19: 30-day cap — must resolve
A20: TD-15 | B20: Retrospective action tracking manual | C20: Process | D20: Low | E20: S-03 | F20: N/A | G20: 2 | H20: L | I20: S-11 | J20: Open | K20: Non-urgent
A23: SUMMARY
A24: Total debt items: | B24: =COUNTA(A5:A300)-COUNTIF(A5:A300,"") -> -252
A25: CRITICAL open: | B25: =COUNTIFS(D5:D300,"CRITICAL",J5:J300,"Open") -> 1
A26: High open: | B26: =COUNTIFS(D5:D300,"High",J5:J300,"Open") -> 3
A27: Total open points: | B27: =SUMIF(J5:J300,"Open",G5:G300) -> 63
A28: Safety debt items: | B28: =COUNTIF(C5:C300,"SAFETY") -> 1

Sheet 9. Code Review Findings
A1: Code Review Findings — Systemic Patterns
A2: Not individual code review comments (those stay in PR). This tab captures SYSTEMIC patterns spotted across reviews that need team-level attention.
A3: Findings drive retro actions, documentation updates, training, or automated lint rules.
A4: Finding ID | B4: Pattern | C4: Category | D4: Occurrences (approx) | E4: First Seen Sprint | F4: Severity | G4: Owner | H4: Remediation Plan | I4: Status
A5: CR-01 | B5: Using Optional.get() without isPresent() check | C5: Quality | D5: 8 | E5: S-01 | F5: Medium | G5: Sr Eng Deputy | H5: Added Checkstyle rule; squad-level training in S-03 | I5: Closed
A6: CR-02 | B6: Audit events missing correlation ID when emitted from async contexts | C6: Safety | D6: 4 | E6: S-02 | F6: High | G6: Sr Eng Deputy | H6: Audit library refactor; correlation context propagation (US-AUDIT-005) | I6: In Progress
A7: CR-03 | B7: Safety-critical precondition checks in conditionals rather than explicit | C7: Safety | D7: 3 | E7: S-03 | F7: High | G7: Sr Eng C | H7: Established precondition evaluator pattern; refactoring sweep | I7: In Progress
A8: CR-04 | B8: Kafka consumer error handling swallows exceptions silently | C8: Resilience | D8: 2 | E8: S-02 | F8: High | G8: Sr Eng A | H8: Standard error handler; topic-specific DLQ | I8: Closed
A9: CR-05 | B9: SQL constructed via string concatenation in a few places | C9: Security | D9: 2 | E9: S-02 | F9: High | G9: Sec Eng | H9: Linted; found-and-fixed; added to pre-commit | I9: Closed
A10: CR-06 | B10: UI components not handling loading/error/empty states consistently | C10: UI | D10: 12 | E10: S-02 | F10: Medium | G10: FE Tech Lead | H10: Component library templates; Storybook checks | I10: In Progress
A11: CR-07 | B11: Integration retries missing jitter (thundering herd risk) | C11: Resilience | D11: 3 | E11: S-03 | F11: Medium | G11: Sr Eng A | H11: Standard retry utility; refactor sweep | I11: Closed
A12: CR-08 | B12: Tests using production-like data volume slow CI | C12: Testing | D12: 5 | E12: S-03 | F12: Low | G12: QA Auto 1 | H12: Test data minimization; fixture sharing | I12: In Progress
A13: CR-09 | B13: Controller methods doing too much — thin-controller guideline not followed | C13: Architecture | D13: 6 | E13: S-02 | F13: Medium | G13: Sr Eng Deputy | H13: Code review checklist emphasis; refactoring examples | I13: Ongoing
A14: CR-10 | B14: Missing district-scope guards on some queries | C14: Security/Safety | D14: 2 | E14: S-03 | F14: High | G14: Sec Eng + Sr Eng Deputy | H14: Audit via code-scan; standard repository base class | I14: In Progress
A15: CR-11 | B15: Logs containing customer identifiers (PII leakage risk) | C15: Security | D15: 3 | E15: S-03 | F15: High | G15: Sec Eng | H15: Log sanitization library; pre-commit scan | I15: Closed
A16: CR-12 | B16: State machine transitions via enum switch rather than explicit machine | C16: Legacy pattern | D16: 4 | E16: S-03 | F16: Medium | G16: Chief Architect | H16: Migrate to state machine library (linked to ADR-017); refactor plan | I16: In Progress

Sheet 10. Build Phase Risks
A1: Build Phase Risk Log
A2: Risks specific to Build phase. Reviewed every 2 sprints by Program Manager + Sr Engs.
A3: CRITICAL or HIGH open risks >4 weeks trigger steering escalation.
A4: Risk ID | B4: Description | C4: Likelihood (1-5) | D4: Impact (1-5) | E4: Score | F4: Mitigation | G4: Owner | H4: Status | I4: Notes
A5: BR-01 | B5: Sprint velocity below committed 4+ sprints running | C5: 3 | D5: 4 | E5: =C5*D5 -> 12 | F5: 3-sprint rolling average tracked; commitment capped at rolling avg * 0.9 | G5: Program Manager | H5: Active
A6: BR-02 | B6: Safety-critical defect escapes to test or UAT | C6: 3 | D6: 5 | E6: =C6*D6 -> 15 | F6: Pair programming; dual code review; Product Council demo before accept; test coverage gates | G6: Sr Eng C | H6: Active
A7: BR-03 | B7: Technical debt accumulates faster than paid down | C7: 4 | D7: 3 | E7: =C7*D7 -> 12 | F7: 15% debt ratio cap; retro walks through debt register; paydown sprints if breached | G7: Sr Eng Deputy | H7: Active | I7: Monitored
A8: BR-04 | B8: Integration with Field Work System blocks entire sprint | C8: 3 | D8: 4 | E8: =C8*D8 -> 12 | F8: Mock/stub for test env; vendor escalation path; alternative batch path designed (TD) | G8: Integration Lead | H8: Active
A9: BR-05 | B9: Key-person dependency on Chief Architect for unblocking | C9: 4 | D9: 4 | E9: =C9*D9 -> 16 | F9: Sr Eng Deputy takes 50% of routine reviews; DAB decisions batched; ADR library mature | G9: Sr Eng Deputy | H9: Active
A10: BR-06 | B10: Mid-engineers ramp slower than planned | C10: 3 | D10: 3 | E10: =C10*D10 -> 9 | F10: Pairing rotation; dedicated mentoring time in capacity; knowledge-share sessions | G10: Sr Engs | H10: Active
A11: BR-07 | B11: Jr engineers taking on too much risk | C11: 2 | D11: 3 | E11: =C11*D11 -> 6 | F11: Safety-critical stories exclude Jr solo; explicit DoR check for story match to engineer | G11: Sr Engs | H11: Active
A12: BR-08 | B12: Test env instability reduces team throughput | C12: 3 | D12: 3 | E12: =C12*D12 -> 9 | F12: DevOps dedicated env maintenance allocation; env health dashboard | G12: DevOps 1 | H12: Active
A13: BR-09 | B13: Requirement changes arriving mid-sprint (scope creep) | C13: 3 | D13: 3 | E13: =C13*D13 -> 9 | F13: Change control process; POs gate in-sprint changes; retro signals | G13: POs + PM | H13: Active
A14: BR-10 | B14: Product Council availability during peak storm periods | C14: 3 | D14: 3 | E14: =C14*D14 -> 9 | F14: Scheduled well in advance; backup operator roster per area; async review for non-demos | G14: Program Manager | H14: Active
A15: BR-11 | B15: Non-MVP feature creeping into MVP | C15: 3 | D15: 4 | E15: =C15*D15 -> 12 | F15: Quarterly MVP scope review with steering; PO discipline; feature flags to defer | G15: POs | H15: Active
A16: BR-12 | B16: Data migration dress rehearsals reveal unresolvable issues | C16: 2 | D16: 4 | E16: =C16*D16 -> 8 | F16: Start rehearsals early in Phase 3; fallback approaches documented for each migration | G16: Data Migration Lead | H16: Active
A17: BR-13 | B17: Storm in region during Build — team impact | C17: 3 | D17: 3 | E17: =C17*D17 -> 9 | F17: Identified backup resources; prioritize finish-current-sprint over starting new | G17: Program Manager | H17: Active
A18: BR-14 | B18: NERC CIP compliance artifacts lag build | C18: 3 | D18: 4 | E18: =C18*D18 -> 12 | F18: Compliance Officer sprint-0 engagement; evidence generation automated where possible | G18: Sec Eng | H18: Active
A19: BR-15 | B19: Tool/license change mid-Build forces rework | C19: 2 | D19: 3 | E19: =C19*D19 -> 6 | F19: Tech debt register includes vendor/license trajectory watchpoints; contingency buffers | G19: Chief Architect | H19: Active

Sheet 11. Build Dashboard
A1: Build Dashboard — KPI Roll-up
A2: Pulls metrics from other tabs. Refreshed weekly by Program Manager. Reviewed in steering monthly.
A3: Thresholds: green within target; amber = watchlist; red = action needed.
A4: Metric | B4: Value | C4: Target | D4: Notes
A5: DELIVERY
A6: DELIVERY
A7: Velocity (3-sprint rolling avg) | B7: ='4. Velocity Tracker'!B25 -> 0 | C7: 60 | D7: Rolling average of completed points
A8: Estimation accuracy | B8: ='4. Velocity Tracker'!B26 -> 0 | C8: >85% | D8: Completed / committed
A9: Total story points completed to date | B9: ='1. Story Backlog'!B50 -> 300 | C9: — | D9: Cumulative
A10: % MVP complete (by points) | B10: ='1. Story Backlog'!B52 -> 4 | C10: Tracking
A12: QUALITY
A13: Defects escaped (cumulative) | B13: ='4. Velocity Tracker'!B27 -> 0 | C13: <5
A14: Defects per sprint (avg completed) | B14: ='4. Velocity Tracker'!B28 -> 0 | C14: <2
A15: Code review findings Open (High/CRITICAL) | B15: =COUNTIFS('9. Code Review Findings'!F5:F200,"High",'9. Code Review Findings'!I5:I200,"Open")+COUNTIFS('9. Code Review Findings'!F5:F200,"High",'9. Code Review Findings'!I5:I200,"In Progress") -> 3 | C15: <=5 | D15: Systemic patterns
A17: HEALTH
A18: Open impediments | B18: =COUNTIF('6. Impediment Log'!H5:H300,"Open")+COUNTIF('6. Impediment Log'!H5:H300,"Escalated") -> 6 | C18: <8 | D18: Active blockers
A19: Escalated impediments | B19: =COUNTIF('6. Impediment Log'!H5:H300,"Escalated") -> 0 | C19: 0
A20: Tech debt open points | B20: =SUMIF('8. Tech Debt Register'!J5:J300,"Open",'8. Tech Debt Register'!G5:G300) -> 63 | C20: <=30 | D20: <=15% of 3-sprint rolling velocity
A21: Tech debt CRITICAL items open | B21: =COUNTIFS('8. Tech Debt Register'!D5:D300,"CRITICAL",'8. Tech Debt Register'!J5:J300,"Open") -> 1 | C21: 0 | D21: 30-day cap per CRITICAL
A22: Safety debt items open | B22: =COUNTIFS('8. Tech Debt Register'!C5:C300,"SAFETY",'8. Tech Debt Register'!J5:J300,"Open") -> 1 | C22: 0 | D22: All must be addressed
A24: RISK
A25: Build risks active (score >=15) | B25: =COUNTIFS('10. Build Phase Risks'!E5:E300,">=15",'10. Build Phase Risks'!H5:H300,"Active") -> 2 | C25: <=2
A26: Build risks active (score 8-14) | B26: =COUNTIFS('10. Build Phase Risks'!E5:E300,">=8",'10. Build Phase Risks'!E5:E300,"<15",'10. Build Phase Risks'!H5:H300,"Active") -> 11 | C26: <=5
A28: FEATURE FLAGS
A29: Active flags | B29: =COUNTIF('7. Feature Flag Register'!I5:I200,"Active") -> 9 | C29: —
A30: Permanent flags (justified) | B30: =COUNTIF('7. Feature Flag Register'!I5:I200,"Permanent") -> 3 | C30: —
